Workbook

Sheet N-01 Cover
A1: Made by Jose Zapatero, jmazsantos@gmail.com
B2: N-01 — Cover and Version Control | K2: TRANSVERSAL
B3: ← Back to Index | D3: Phase: TRANSVERSAL / EXAM | Data required: None | Min. sample: n/a | Complexity: 1/5 | Typical output: Version record and block map
B5: PURPOSE
B7: This workbook is a complete Lean Six Sigma Black Belt toolkit built to do two jobs at the same time.
B8: Job A - exam preparation: it covers the Body of Knowledge to the standard required by an ASQ or IASSC Black Belt examination, with correct theory, formulas, worked derivations and self-test questions.
B10: Job B - live project tool: every tool sheet contains a working calculator that accepts real data from the PET and keg lines and returns an answer together with an explicit decision rule. Nothing is hardcoded; every result is a live Excel formula.
B12: Neither job outranks the other. A sheet that teaches but does not calculate is incomplete, and so is the reverse.
B14: IDENTIFICATION
B16: Workbook | C16: LSSBB_Toolkit_v6_4.xlsx
B17: Version | C17: v6.4 - Delivery 6 of 6 - COMPLETE (all 130 sheets built and QA passed)
B18: Owner | C18: Jose Zapatero - Packaging and Manufacturing Excellence Manager
B19: Organisation | C19: Cerveceria Cubana - Royal Swinkels Family Brewers
B20: Reference operation | C20: PET line 18,000 BPH, 24/7, shifts A/B/C/D; keg line Monobloc 80 (4-2)
B21: Total sheets | C21: 130
B22: Language | C22: English (sheet U-05 is bilingual EN-ES by design)
B23: Macros | C23: None. No VBA, no external links, no Power Query.
B25: BLOCK MAP
B27: Block | C27: Content | D27: Sheets | E27: Built in delivery
B28: N | C28: Navigation | D28: 8 | E28: 1
B29: E | C29: Statistics | D29: 60 | E29: 2, 3, 4
B30: L | C30: Lean and Improvement | D30: 26 | E30: 5
B31: H | C31: Quality and Problem Solving | D31: 16 | E31: 5
B32: G | C32: Project and Change Management | D32: 10 | E32: 6
B33: U | C33: Utilities and Exam Preparation | D33: 10 | E33: 6
B34: TOTAL | D34: 130 | E34: 1 to 6
B36: VERSION HISTORY
B38: Version | C38: Date | D38: Delivery | E38: Change | F38: Author
B39: v6.0 | C39: 2026-07-26 | D39: 1 of 6 | E39: All 130 sheets created. Navigation layer N-01 to N-08 built in full. Every tool sheet stubbed so that all index hyperlinks resolve. | F39: Jose Zapatero
B40: v6.1 | C40: 2026-07-27 | D40: 2 of 6 | E40: Statistics Levels 0-2 built in full (E-01 to E-21): data types, distributions, sampling, central limit theorem simulation, confidence intervals, hypothesis framework, sample size, statistical vs practical significance. | F40: Jose Zapatero
B41: v6.1 | C41: 2026-07-27 | D41: 3 of 6 | E41: Hypothesis testing and regression built in full (E-22 to E-40): all parametric and nonparametric tests, ANOVA, variance tests, normality testing, correlation and regression, multi-vari analysis. | F41: Jose Zapatero
B42: v6.2 | C42: 2026-07-27 | D42: 4 of 6 | E42: DOE, SPC, capability and MSA built in full (E-41 to E-60): full and fractional factorials, screening designs, centre points and response surface methods; I-MR, Xbar-R, Xbar-S, p/np, c/u, Laney p'/u', CUSUM/EWMA control charts and Nelson rules; Cp/Cpk/Pp/Ppk/Cpm capability and Z-bench; Gage R&R (ANOVA) and full MSA (bias, linearity, stability, attribute agreement). | F42: Jose Zapatero
B43: v6.3 | C43: 2026-07-27 | D43: 5 of 6 | E43: Lean and Quality tools built in full (L-01 to L-26, H-01 to H-16): wastes, VSM, takt, Little's Law, TOC, line balancing, OEE with the six big losses, 5S, standard work, SMED, TPM, poka-yoke, jidoka, kanban, heijunka, kaizen, gemba, PDCA, Pugh selection, pilot confirmation, charter, SIPOC, VOC/CTQ, Kano, check sheets, Pareto, histogram and box plot, run chart, stratification, Ishikawa, 5 Whys, C&E matrix, FMEA with AIAG-VDA Action Priority, A3, 8D and the control plan with a three-level reaction plan. | F43: Jose Zapatero
B44: v6.4 | C44: 2026-07-28 | D44: 6 of 6 | E44: Project management and utilities built in full (G-01 to G-10, U-01 to U-10): project selection, COPQ business case, stakeholder analysis, RACI, communication plan, ADKAR change management, risk register, PERT/CPM schedule with Gantt, benefit validation and closure with replication; plus statistical tables, control chart constants, Excel function guide, master formula sheet, 236-term EN-ES glossary, universal sample size calculator, example data bank and three 40-question exam banks. Final QA passed: 130 sheets, zero formula errors. | F44: Jose Zapatero
B46: Add one row per delivery. Do not overwrite history rows.

Sheet N-02 How To Use
A1: Made by Jose Zapatero, jmazsantos@gmail.com
B2: N-02 — How To Use This Workbook | K2: TRANSVERSAL
B3: ← Back to Index | D3: Phase: TRANSVERSAL / EXAM | Data required: None | Min. sample: n/a | Complexity: 1/5 | Typical output: Colour legend and sheet anatomy
B5: IF YOU ONLY READ ONE THING
B7: Do not start from the list of tools. Start from your problem.
B8: Open N-06 Index by Problem, find the archetype that matches what is happening on the line, and follow the numbered route.
B9: Every step in that route is a hyperlink to a sheet that produces one specific, named output.
B10: → Go to N-06 Index by Problem
B12: COLOUR LEGEND
B14: YELLOW = overwrite with your data | C14: GREEN = calculated automatically
B16: Colour | C16: Meaning | D16: May I type in it?
B17: Yellow fill, gold border | C17: Input cell. Pre-filled with a realistic packaging example. | D17: Yes - overwrite freely
B18: Green fill, green border | C18: Calculated cell. Contains a live Excel formula. | D18: No - it will recalculate itself
B19: Dark blue band | C19: Section header inside a sheet. | D19: No
B20: Mid blue band | C20: Table header row. | D20: No
B21: Blue underlined text | C21: Internal hyperlink to another sheet. | D21: No - click it
B23: ANATOMY OF A TOOL SHEET
B25: Every sheet in blocks E, L, H and G follows the same structure, in the same order, so that the decision rule is always in the same place.
B27: Block | C27: What it contains | D27: Why it is there
B28: Title bar (rows 1-3) | C28: Sheet ID, full title, phase chip, back link and the metadata strip. | D28: Tells you in one glance what the sheet needs and what it gives back.
B29: 1. Quick Card | C29: Three lines: what question it answers, when you would reach for it, what it gives you. | D29: The block you read when scanning for the right tool.
B30: 2. Concept | C30: Four to eight lines of plain English before any symbol appears. | D30: Understanding the logic prevents the classic misuse of the tool.
B31: 3. When to use / not use / assumptions | C31: Two short lists, then an assumption table: assumption, how to check it, what to do if it fails. | D31: Most wrong conclusions come from a violated assumption, not from arithmetic.
B32: 4. Formula and derivation | C32: The formula in readable notation, every symbol defined, degrees of freedom stated. | D32: This block serves the examination.
B33: 5. Excel implementation | C33: The exact functions used on the sheet and what each argument means. | D33: So you can rebuild the calculation in your own file.
B34: 6. Worked example (interactive) | C34: A realistic PET or keg scenario, yellow inputs, green live formulas. | D34: This block serves the factory floor.
B35: 7. Decision rule and interpretation | C35: A verdict cell driven by a formula, a numeric criteria table, and common mistakes. | D35: A number without a decision rule changes nothing.
B36: 8. Self-check | C36: Three exam-style questions, answers hidden in white font in column N. | D36: Select the cell in column N to reveal the answer.
B37: 9. Related sheets | C37: Previous tool, next tool, and the alternative if assumptions fail. | D37: Keeps you moving along a route instead of hunting.
B39: FOUR WAYS TO NAVIGATE
B41: Start from | C41: Use this sheet | D41: Best when
B42: A DMAIC phase | C42: N-03 Index DMAIC | D42: You are running a project and need the phase toolset.
B43: A question in plain language | C43: N-04 Index by Question | D43: You know what you want to know but not what it is called.
B44: Your data types | C44: N-05 Test Selector | D44: You need the correct statistical test and its alternative.
B45: A problem on the line | C45: N-06 Index by Problem | D45: Something is wrong today and you need a route, not a catalogue.
B47: Two further routes: N-07 Tollgates tells you whether you may close a phase, and N-08 Fast Track Routes tells you whether a full DMAIC is the right vehicle at all.
B50: TECHNICAL NOTES
B52: • All calculations are live Excel formulas. There are no macros and no VBA, so the file opens and recalculates on any machine, including a locked-down plant PC.
B53: • There are no external links and no Power Query connections. The workbook is self-contained.
B54: • No sheet is protected. Everything is editable - which also means every formula is deletable. Keep a clean master copy and work on duplicates for live projects.
...

Sheet N-03 Index DMAIC
A1: Made by Jose Zapatero, jmazsantos@gmail.com
B2: N-03 — Master Index by DMAIC Phase | K2: TRANSVERSAL
B3: ← Back to Index | D3: Phase: TRANSVERSAL / EXAM | Data required: None | Min. sample: n/a | Complexity: 1/5 | Typical output: Filterable master list of 130 sheets
B5: ID | C5: Tool | D5: Block | E5: Phase | F5: What question it answers | G5: Data required | H5: Min. sample | I5: Complexity 1-5 | J5: Output produced | K5: Go
B6: DEFINE (9 sheets)
B7: H-01 | C7: Project Charter | D7: H | E7: D | F7: What exactly am I solving, why and by when? | G7: Problem, goal, scope, benefit | H7: n/a | I7: 2 | J7: Signed one-page charter | K7: Go →
B8: H-02 | C8: SIPOC | D8: H | E8: D | F8: What are the boundaries of my process? | G8: Process walk | H8: n/a | I8: 1 | J8: High-level SIPOC map | K8: Go →
B9: H-03 | C9: Voice of the Customer and CTQ Tree | D9: H | E9: D | F9: What does the customer need, in measurable terms? | G9: Customer statements | H9: n/a | I9: 2 | J9: CTQ tree with measurable specs | K9: Go →
B10: H-04 | C10: Kano Model | D10: H | E10: D | F10: Which features delight and which are expected? | G10: Customer survey | H10: n/a | I10: 2 | J10: Kano classification of attributes | K10: Go →
B11: G-01 | C11: Project Selection and Portfolio Prioritisation | D11: G | E11: D | F11: Which project should we do first? | G11: Candidate projects and criteria | H11: n/a | I11: 2 | J11: Scored and ranked project portfolio | K11: Go →
B12: G-02 | C12: Business Case and Cost of Poor Quality | D12: G | E12: D | F12: What is this problem costing us? | G12: Loss volumes and unit costs | H12: n/a | I12: 3 | J12: COPQ by category and business case | K12: Go →
B13: G-03 | C13: Stakeholder Analysis | D13: G | E13: D | F13: Who can block or accelerate this project? | G13: Stakeholder list | H13: n/a | I13: 2 | J13: Power-interest grid and engagement plan | K13: Go →
B14: G-04 | C14: RACI Matrix | D14: G | E14: D | F14: Who is responsible for each deliverable? | G14: Deliverables and roles | H14: n/a | I14: 1 | J14: Validated RACI with conflict check | K14: Go →
B15: G-05 | C15: Communication Plan | D15: G | E15: D | F15: Who hears what, how often, from whom? | G15: Audiences and messages | H15: n/a | I15: 1 | J15: Communication calendar | K15: Go →
B16: MEASURE (31 sheets)
B17: E-01 | C17: Data Types and Measurement Scales | D17: E | E17: M | F17: What kind of data am I holding and what may I do with it? | G17: Any variable list | H17: n/a | I17: 1 | J17: Data classification and permitted statistics | K17: Go →
B18: E-02 | C18: Population, Sample and Sampling Error | D18: E | E18: M | F18: How far can my sample be from the truth? | G18: Sample values | H18: 5 | I18: 1 | J18: Sampling error estimate | K18: Go →
B19: E-03 | C19: Descriptive Statistics: Centre and Spread | D19: E | E19: M | F19: Where is my process centred and how wide is it? | G19: Continuous measurements | H19: 10 | I19: 1 | J19: Mean, median, StDev, range, quartiles, histogram | K19: Go →
B20: E-04 | C20: Distribution Shape: Skewness and Kurtosis | D20: E | E20: M | F20: Is my distribution symmetric and how heavy are the tails? | G20: Continuous measurements | H20: 25 | I20: 2 | J20: Skewness and kurtosis with interpretation | K20: Go →
B21: E-05 | C21: Sampling Strategies and Rational Subgrouping | D21: E | E21: M | F21: How and when should I take my samples? | G21: Process timeline and sources | H21: n/a | I21: 3 | J21: Sampling plan and subgroup definition | K21: Go →
B22: E-06 | C22: Operational Definitions and Data Collection Plan | D22: E | E22: M | F22: Will two people record the same thing the same way? | G22: Process and metric list | H22: n/a | I22: 2 | J22: Operational definitions and collection plan | K22: Go →
B23: E-07 | C23: The Normal Distribution and Z Scores | D23: E | E23: M | F23: What proportion of output falls beyond this limit? | G23: Mean, StDev, limit | H23: n/a | I23: 2 | J23: Z score, tail probability, PPM | K23: Go →
B24: E-08 | C24: Central Limit Theorem (Live Simulation) | D24: E | E24: M | F24: Why can I use normal theory on non-normal data? | G24: None (simulated) | H24: n/a | I24: 3 | J24: Raw vs sample-mean histograms | K24: Go →
B25: E-09 | C25: The t, Chi-Square and F Distributions | D25: E | E25: M | F25: Which reference distribution does my test use? | G25: Degrees of freedom, alpha | H25: n/a | I25: 3 | J25: Critical values and tail areas | K25: Go →
B26: E-10 | C26: Binomial Distribution (Defective Units) | D26: E | E26: M | F26: What is the chance of x defective bottles in n? | G26: n, p, x | H26: n/a | I26: 2 | J26: Binomial probabilities and cumulative curve | K26: Go →
B27: E-11 | C27: Poisson Distribution (Defects per Unit) | D27: E | E27: M | F27: What is the chance of x micro-stops in a shift? | G27: Mean rate, exposure | H27: n/a | I27: 2 | J27: Poisson probabilities and rate comparison | K27: Go →
B28: E-12 | C28: Weibull, Exponential and Lognormal | D28: E | E28: M | F28: How do I model time to failure or skewed data? | G28: Times to event | H28: 15 | I28: 4 | J28: Fitted shape and scale, reliability estimate | K28: Go →
B29: E-13 | C29: Identifying the Distribution of Your Data | D29: E | E29: M | F29: Which distribution actually fits my data? | G29: Continuous measurements | H29: 25 | I29: 4 | J29: Ranked candidate distributions | K29: Go →
B30: E-14 | C30: Standard Error vs Standard Deviation | D30: E | E30: M | F30: How precise is my estimate of the mean? | G30: StDev and n | H30: 5 | I30: 2 | J30: Standard error and precision statement | K30: Go →
B31: E-15 | C31: Confidence Intervals for the Mean | D31: E | E31: M | F31: Within what range does the true mean sit? | G31: Sample mean, StDev, n | H31: 5 | I31: 2 | J31: Confidence interval for the mean | K31: Go →
B32: E-16 | C32: Confidence Intervals for Proportion and Std Dev | D32: E | E32: M | F32: Within what range sits my true defect rate or spread? | G32: x, n or StDev, n | H32: 20 | I32: 3 | J32: Confidence intervals for p and sigma | K32: Go →
B33: E-20 | C33: Sample Size Determination | D33: E | E33: M | F33: How many samples do I actually need? | G33: Alpha, power, delta, sigma | H33: n/a | I33: 3 | J33: Required n for four scenarios | K33: Go →
B34: E-57 | C34: Cp, Cpk, Pp, Ppk and Cpm | D34: E | E34: M | F34: Can my process meet the specification? | G34: Measurements plus spec limits | H34: 30 | I34: 3 | J34: Capability indices, PPM, capability histogram | K34: Go →
B35: E-58 | C35: Non-Normal and Attribute Capability, Z-bench | D35: E | E35: M | F35: How do I state capability when data is not normal? | G35: Non-normal or attribute data | H35: 30 | I35: 4 | J35: Z-bench, sigma level, PPM | K35: Go →
B36: E-59 | C36: Gage R&R: ANOVA and Range Methods | D36: E | E36: M | F36: Can I trust my measurement system? | G36: 10 parts x 3 operators x 2 trials | H36: 60 | I36: 5 | J36: %GRR, ndc and AIAG verdict | K36: Go →
B37: E-60 | C37: MSA: Bias, Linearity, Stability, Attribute Agreement | D37: E | E37: M | F37: Is my gauge biased, drifting or disagreeing? | G37: Reference standards, repeat readings | H37: 30 | I37: 4 | J37: Bias, linearity, stability, Cohen's Kappa | K37: Go →
B38: L-02 | C38: Value Stream Map - Current State | D38: L | E38: M | F38: What does the whole flow look like today? | G38: Cycle times, inventories, uptime | H38: n/a | I38: 4 | J38: Current state map and lead time ladder | K38: Go →
B39: L-04 | C39: Process Mapping and Swimlane Flowcharts | D39: L | E39: M | F39: What are the real steps and handoffs? | G39: Process walk notes | H39: n/a | I39: 2 | J39: Swimlane map with decision points | K39: Go →
B40: L-05 | C40: Spaghetti Diagram | D40: L | E40: M | F40: How far do people and materials actually travel? | G40: Layout and movement log | H40: n/a | I40: 2 | J40: Distance total and travel map | K40: Go →
B41: L-07 | C41: Takt Time, Cycle Time and Lead Time | D41: L | E41: M | F41: Is my line fast enough for demand? | G41: Demand, available time, cycle times | H41: n/a | I41: 2 | J41: Takt vs cycle comparison | K41: Go →
...

Sheet N-04 Index by Question
A1: Made by Jose Zapatero, jmazsantos@gmail.com
B2: N-04 — Index by Type of Question | K2: TRANSVERSAL
B3: ← Back to Index | D3: Phase: TRANSVERSAL / EXAM | Data required: None | Min. sample: n/a | Complexity: 1/5 | Typical output: Tools grouped under nine questions
B5: You rarely know the name of the tool you need. You do know the question. Find your question below and work down the list.
B7: 1. What is my process actually doing?
B8: ID | C8: Tool | D8: Why this tool answers the question | E8: Phase
B9: H-02 | C9: SIPOC | D9: Fixes the boundaries before anyone argues about scope | E9: D
B10: L-04 | C10: Process Mapping and Swimlane Flowcharts | D10: Shows the real steps, handoffs and rework loops | E10: M
B11: L-22 | C11: Gemba Walk | D11: Confirms on the floor what the map claims | E11: M
B12: E-03 | C12: Descriptive Statistics: Centre and Spread | D12: Quantifies centre and spread of the key output | E12: M
B13: H-07 | C13: Histogram and Box Plot | D13: Shows the shape of the distribution | E13: M
B14: H-08 | C14: Run Chart and Trend Analysis | D14: Shows behaviour over time before any limits are drawn | E14: M
B15: L-11 | C15: Overall Equipment Effectiveness | D15: Converts calendar time into OEE and the six big losses | E15: M
B17: 2. Can I trust my data?
B18: ID | C18: Tool | D18: Why this tool answers the question | E18: Phase
B19: E-06 | C19: Operational Definitions and Data Collection Plan | D19: Operational definitions: two people, same reading | E19: M
B20: E-01 | C20: Data Types and Measurement Scales | D20: Confirms which statistics the data type permits | E20: M
B21: E-05 | C21: Sampling Strategies and Rational Subgrouping | D21: Rational subgrouping: sample so that the chart can work | E21: M
B22: E-59 | C22: Gage R&R: ANOVA and Range Methods | D22: Gage R&R: how much of the observed variation is the gauge | E22: M
B23: E-60 | C23: MSA: Bias, Linearity, Stability, Attribute Agreement | D23: Bias, linearity, stability and attribute agreement | E23: M
B24: E-20 | C24: Sample Size Determination | D24: Confirms the sample is large enough to conclude anything | E24: M
B26: 3. Is my process stable?
B27: ID | C27: Tool | D27: Why this tool answers the question | E27: Phase
B28: E-47 | C28: Common Cause vs Special Cause Variation | D28: Common cause vs special cause before you react | E28: C
B29: E-48 | C29: Control Chart Selection Tree | D29: Selects the correct chart for your data type | E29: C
B30: E-49 | C30: Individuals and Moving Range Chart | D30: I-MR for individual measurements | E30: C
B31: E-50 | C31: Xbar-R Chart | D31: Xbar-R for small subgroups | E31: C
B32: E-51 | C32: Xbar-S Chart | D32: Xbar-S for subgroups of nine or more | E32: C
B33: E-52 | C33: p and np Charts | D33: p and np for defective units | E33: C
B34: E-53 | C34: c and u Charts | D34: c and u for defects per unit | E34: C
B35: E-54 | C35: Laney p' and u' Charts (Overdispersion) | D35: Laney p' and u' when subgroups are very large | E35: C
B36: E-55 | C36: CUSUM and EWMA Charts | D36: CUSUM and EWMA for small sustained shifts | E36: C
B37: E-56 | C37: Western Electric and Nelson Rules | D37: Western Electric and Nelson pattern rules | E37: C
B39: 4. Is my process capable?
B40: ID | C40: Tool | D40: Why this tool answers the question | E40: Phase
B41: E-57 | C41: Cp, Cpk, Pp, Ppk and Cpm | D41: Cp, Cpk, Pp, Ppk, Cpm and PPM against specification | E41: M
B42: E-58 | C42: Non-Normal and Attribute Capability, Z-bench | D42: Capability when the data is not normal or is attribute | E42: M
B43: E-07 | C43: The Normal Distribution and Z Scores | D43: Z scores and tail probabilities behind the indices | E43: M
B44: E-21 | C44: Statistical vs Practical Significance | D44: Whether the gap matters commercially, not just statistically | E44: A
B46: 5. Are these groups different?
...

Sheet N-05 Test Selector
A1: Made by Jose Zapatero, jmazsantos@gmail.com
B2: N-05 — Statistical Test Selector (Y vs X Matrix) | K2: TRANSVERSAL
B3: ← Back to Index | D3: Phase: TRANSVERSAL / EXAM | Data required: Type of Y and type of X | Min. sample: n/a | Complexity: 2/5 | Typical output: Named test plus nonparametric alternative
B5: THE Y VERSUS X GRID
B7: Rows: the type of your Y (the output you measure). Columns: the type of your X (what you think changes it).
B8: Upper line in each cell = the standard test. Lower line = the alternative when its assumptions fail. Both are hyperlinks.
B10: Y \ X | C10: X = none (compare with a target) | D10: X = two groups | E10: X = three or more groups | F10: X = continuous
B11: Y continuous (fill volume, torque, PU) | C11: 1-Sample t-Test | D11: 2-Sample t-Test (Welch) Paired t if same units | E11: One-Way ANOVA + Tukey | F11: Correlation then Regression
C12: NP: Wilcoxon signed rank | D12: NP: Mann-Whitney | E12: NP: Kruskal-Wallis | F12: NP: Spearman rho
B13: Y binary (pass/fail, leaking keg) | C13: 1-Proportion Test | D13: 2-Proportion Test | E13: Chi-Square test of independence | F13: Binary Logistic Regression
C14: Exact binomial | D14: Fisher exact if counts are small | E14: Fisher exact | F14: Stratify and use Chi-Square
B15: Y count (micro-stops, label defects) | C15: 1-Sample Poisson rate test | D15: 2-Sample Poisson rate test | E15: Chi-Square on a count table | F15: Regression on the rate (log link approx.)
C16: u-chart against a standard rate | D16: Chi-Square on counts | E16: Compare u-charts by group | F16: Bin X and use Chi-Square
B17: Y ordinal (taste panel score, severity 1-5) | C17: Sign test / Wilcoxon signed rank | D17: Mann-Whitney | E17: Kruskal-Wallis | F17: Spearman rank correlation
C18: Treat as continuous with caution | D18: Chi-Square on collapsed categories | E18: Chi-Square on collapsed categories | F18: Ordinal logistic (out of scope)
B20: DECISION LADDER
B22: START: name the Y (the output you care about) and the X (what you suspect changes it).
B23: Is the Y continuous, binary, a count, or ordinal? -> choose the row in the grid above.
B24: Is the X absent, two groups, three or more groups, or continuous? -> choose the column.
B25: IF Y IS CONTINUOUS, three questions remain before you run the test:
B26: Q1. Is the data approximately normal? Test it on E-32.
B27: Yes -> continue to Q2.
B28: No -> transform on E-33, or jump straight to the nonparametric alternative on E-31.
B29: Q2. Are the group variances comparable? Test it on E-28.
B30: Yes -> pooled t-test or standard ANOVA is available.
B31: No -> use Welch on E-24, or Welch ANOVA / Kruskal-Wallis.
B32: Q3. Are the observations paired (same bottle, same keg, same mould cavity before and after)?
... B43: ASSUMPTION FOOTER STRIP
B45: Check | C45: Sheet | D45: What it tells you
B46: Normality | C46: E-32 Normality Testing and Probability Plots | D46: Whether the parametric test is legitimate at all
B47: Equality of variance | C47: E-28 Tests for Variance: F, Levene, Bartlett | D47: Whether to pool or to use Welch
B48: Assumption failure route | C48: E-33 When Assumptions Fail: Transformations and Alternatives | D48: Transformation or nonparametric alternative
B49: Sample size and power | C49: E-20 Sample Size Determination | D49: Whether a non-significant result means anything

Sheet N-06 Index by Problem
A1: Made by Jose Zapatero, jmazsantos@gmail.com
B2: N-06 — Index by Problem Archetype | K2: TRANSVERSAL
B3: ← Back to Index | D3: Phase: TRANSVERSAL / EXAM | Data required: Problem statement | Min. sample: n/a | Complexity: 2/5 | Typical output: Numbered tool route with expected outputs
B5: Twelve problem archetypes taken from this operation. Find yours, then follow the numbered route.
B6: Each step names the sheet to use and the output you should hold before moving on to the next step.
B8: No. | C8: Archetype | D8: Typical symptom on the floor | E8: Typical duration
B9: 1 | C9: Excessive variability in a measured characteristic | D9: Fill volumes swing from 495 to 508 ml on the same SKU within one shift. | E9: 6-10 weeks
B10: 2 | C10: Process off-target / centring problem | D10: Average fill sits at 503 ml against a 500 ml target: three millilitres given away per bottle. | E10: 3-6 weeks
B11: 3 | C11: High defect or rejection rate (attribute) | D11: Innocheck FBI rejects 1.8% of bottles; target is below 0.5%. | E11: 6-10 weeks
B12: 4 | C12: Unplanned downtime and micro-stops | D12: Innopal and Robopac produce 40 to 60 micro-stops per shift, none longer than two minutes. | E12: 8-12 weeks
B13: 5 | C13: Slow changeover between formats | D13: A 1.5 L to 0.5 L change takes 95 minutes and varies by 30 minutes between shifts. | E13: 4-6 weeks (Kaizen)
B14: 6 | C14: Material loss / yield / shrinkage | D14: PET preform consumption runs 2.4% above theoretical; label loss above 3%. | E14: 8-12 weeks
B15: 7 | C15: Long cycle time or low throughput | D15: Nominal 18,000 BPH but the real average over a week is 13,400 BPH. | E15: 8-12 weeks
B16: 8 | C16: Customer complaint or market incident | D16: Distributor reports flat product and low CO2 in a specific batch. | E16: 1 day containment, 60 days closure
B17: 9 | C17: Difference between shifts, machines or operators | D17: Shift C consistently fills 1.5 ml higher than Shift A on the same SKU. | E17: 4-8 weeks
B18: 10 | C18: Measurement disagreement between operators or instruments | D18: Laboratory and line CO2 readings differ by 0.3 g/L on the same sample. | E18: 3-5 weeks
B19: 11 | C19: Safety incident or near miss | D19: Operator near miss during a manual jam clearance on the Innoket with the guard defeated. | E19: 24 h containment, 30-60 days closure
B20: 12 | C20: Cost overrun on a consumable | D20: Glue, film and CO2 consumption per 1,000 bottles is 12% above standard. | E20: 6-8 weeks
B23: ARCHETYPE 1 — Excessive variability in a measured characteristic
B24: What it is: The average is fine but the spread is too wide to hold the specification.
B25: How it shows up: Fill volumes swing from 495 to 508 ml on the same SKU within one shift.
B26: Typical duration: 6-10 weeks | Steps: 10
B28: Step | C28: Tool (click to open) | D28: Output you should hold before moving on | E28: Phase
B29: 1 | C29: H-02 SIPOC | D29: Process boundaries and the exact characteristic agreed | E29: D
B30: 2 | C30: E-06 Operational Definitions and Data Collection Plan | D30: Operational definition and a sampling plan that can detect the shift | E30: M
B31: 3 | C31: E-59 Gage R&R: ANOVA and Range Methods | D31: %GRR: proof the spread is the process, not the gauge | E31: M
B32: 4 | C32: E-03 Descriptive Statistics: Centre and Spread | D32: Baseline mean, StDev and shape | E32: M
B33: 5 | C33: E-50 Xbar-R Chart | D33: Chart showing whether the spread is stable or erratic | E33: C
B34: 6 | C34: E-57 Cp, Cpk, Pp, Ppk and Cpm | D34: Cp vs Cpk: separates spread problems from centring problems | E34: M
B35: 7 | C35: E-40 Multi-Vari Analysis | D35: Dominant family of variation: valve, cavity, shift or time | E35: A
B36: 8 | C36: E-26 One-Way ANOVA with Tukey HSD | D36: Statistical confirmation of the difference between valves or cavities | E36: A
B37: 9 | C37: E-42 Full Factorial Designs (2^k) | D37: Settings that reduce the spread, tested rather than argued | E37: I
B38: 10 | C38: H-16 Control Plan and Reaction Plan (OCAP) | D38: Control plan and reaction plan that hold the new sigma | E38: C
C39: ↑ Back to the archetype list
B41: ARCHETYPE 2 — Process off-target / centring problem
B42: What it is: The spread is acceptable but the average sits away from the nominal value.
B43: How it shows up: Average fill sits at 503 ml against a 500 ml target: three millilitres given away per bottle.
B44: Typical duration: 3-6 weeks | Steps: 10
B46: Step | C46: Tool (click to open) | D46: Output you should hold before moving on | E46: Phase
B47: 1 | C47: E-06 Operational Definitions and Data Collection Plan | D47: Agreed measurement method and sampling frequency | E47: M
...

Sheet N-07 Tollgates
A1: Made by Jose Zapatero, jmazsantos@gmail.com
B2: N-07 — Phase Tollgate Checklists | K2: TRANSVERSAL
B3: ← Back to Index | D3: Phase: TRANSVERSAL / EXAM | Data required: Project deliverables | Min. sample: n/a | Complexity: 2/5 | Typical output: Percentage complete per phase and readiness
B5: A tollgate is not a formality. It is the moment the Champion asks whether the phase produced what it was supposed to produce.
B6: Answer Yes or No in the yellow column. The percentage complete and the verdict update themselves.
B8: YELLOW = overwrite with your data | C8: GREEN = calculated automatically
B10: DEFINE TOLLGATE
B11: Deliverable | C11: Produced on | D11: Acceptance question the Champion will ask | E11: Done?
B12: Approved project charter | C12: H-01 Project Charter | D12: Is the problem statement free of causes and solutions? | E12: No
B13: Business case with COPQ | C13: G-02 Business Case and Cost of Poor Quality | D13: Has Finance agreed the size of the prize? | E13: No
B14: Process boundaries agreed | C14: H-02 SIPOC | D14: Do we know where the project starts and stops? | E14: No
B15: Customer needs translated to CTQ | C15: H-03 Voice of the Customer and CTQ Tree | D15: Is every CTQ measurable with a specification? | E15: No
B16: Stakeholders mapped and engaged | C16: G-03 Stakeholder Analysis | D16: Does anyone with veto power still oppose this? | E16: No
B17: RACI agreed | C17: G-04 RACI Matrix | D17: Does every deliverable have exactly one Accountable? | E17: No
B18: Risks identified | C18: G-07 Project Risk Register | D18: Do we know what would kill this project? | E18: No
B19: Phase complete | D19: =IF(E19=1,"TOLLGATE PASSED - phase may be closed",IF(E19>=0.8,"NEARLY THERE - close the remaining gaps","NOT READY - do not book the review yet")) -> NOT READY - do not book the review yet | E19: =IFERROR(COUNTIF(E12:E18,"Yes")/COUNTA(E12:E18),0) -> 0
B21: MEASURE TOLLGATE
B22: Deliverable | C22: Produced on | D22: Acceptance question the Champion will ask | E22: Done?
B23: Detailed process map | C23: L-04 Process Mapping and Swimlane Flowcharts | D23: Does the map show the process as it is, not as designed? | E23: No
B24: Operational definitions and data collection plan | C24: E-06 Operational Definitions and Data Collection Plan | D24: Would two operators record the same value? | E24: No
B25: Measurement system validated | C25: E-59 Gage R&R: ANOVA and Range Methods | D25: Is %GRR below 10% of study variation (30% is the limit)? | E25: No
B26: Sample size justified | C26: E-20 Sample Size Determination | D26: Is the sample large enough to detect the effect we care about? | E26: No
B27: Baseline data collected | C27: E-03 Descriptive Statistics: Centre and Spread | D27: Do we have at least 25 stable subgroups? | E27: No
B28: Process stability assessed | C28: E-49 Individuals and Moving Range Chart | D28: Is the baseline free of unexplained special causes? | E28: No
B29: Baseline capability stated | C29: E-57 Cp, Cpk, Pp, Ppk and Cpm | D29: Do we have a Cpk or a sigma level everyone accepts? | E29: No
B30: Phase complete | D30: =IF(E30=1,"TOLLGATE PASSED - phase may be closed",IF(E30>=0.8,"NEARLY THERE - close the remaining gaps","NOT READY - do not book the review yet")) -> NOT READY - do not book the review yet | E30: =IFERROR(COUNTIF(E23:E29,"Yes")/COUNTA(E23:E29),0) -> 0
B32: ANALYZE TOLLGATE
B33: Deliverable | C33: Produced on | D33: Acceptance question the Champion will ask | E33: Done?
B34: Potential causes generated | C34: H-10 Ishikawa / Fishbone Diagram | D34: Did the list come from the people who run the process? | E34: No
B35: Causes screened and ranked | C35: H-12 Cause and Effect (X-Y) Matrix | D35: Are the vital few X's named and prioritised? | E35: No
B36: Data stratified | C36: H-09 Stratification | D36: Have we looked inside every obvious subgroup? | E36: No
B37: Hypotheses tested statistically | C37: E-22 Hypothesis Test Selection Roadmap | D37: Is each root cause supported by a p-value or a chart? | E37: No
B38: Assumptions verified | C38: E-32 Normality Testing and Probability Plots | D38: Was normality and equal variance checked before the test? | E38: No
B39: Root cause validated, not assumed | C39: H-11 5 Whys | D39: Can we turn the problem on and off at will? | E39: No
B40: Practical significance confirmed | C40: E-21 Statistical vs Practical Significance | D40: Is the effect large enough to justify a solution? | E40: No
B41: Phase complete | D41: =IF(E41=1,"TOLLGATE PASSED - phase may be closed",IF(E41>=0.8,"NEARLY THERE - close the remaining gaps","NOT READY - do not book the review yet")) -> NOT READY - do not book the review yet | E41: =IFERROR(COUNTIF(E34:E40,"Yes")/COUNTA(E34:E40),0) -> 0
B43: IMPROVE TOLLGATE
B44: Deliverable | C44: Produced on | D44: Acceptance question the Champion will ask | E44: Done?
B45: Solutions generated | C45: L-24 Idea Generation: Brainwriting, SCAMPER | D45: Did we go beyond the first obvious idea? | E45: No
B46: Solutions selected with criteria | C46: L-25 Pugh Matrix, Impact-Effort, Weighted Criteria | D46: Was the choice scored rather than argued? | E46: No
...

Sheet N-08 Fast Track Routes
A1: Made by Jose Zapatero, jmazsantos@gmail.com
B2: N-08 — When Not To Run a Full DMAIC | K2: TRANSVERSAL
B3: ← Back to Index | D3: Phase: TRANSVERSAL / EXAM | Data required: Five screening answers | Min. sample: n/a | Complexity: 2/5 | Typical output: Recommended methodology route
B5: Knowing when NOT to run a full DMAIC is a Black Belt judgement.
B6: A four-month project aimed at a problem whose cause is already known destroys credibility faster than any failed hypothesis test.
B9: THE FIVE ROUTES COMPARED
B10: Route | C10: When to use it | D10: Typical duration | E10: Data requirement | F10: Who leads it | G10: Link
B11: Full DMAIC | C11: Root cause is unknown and the answer needs data and statistics | D11: 3-6 months | E11: High: baseline, MSA, hypothesis tests, capability | F11: Black Belt or trained Green Belt | G11: Open →
B12: Kaizen Event | C12: Cause is understood, the solution is known or close, and the work is hands-on | D12: 1 week plus 30 days follow-up | E12: Medium: time studies and before/after data | F12: Facilitator with a cross-functional team | G12: Open →
B13: A3 | C13: A single well-bounded problem needing structured thinking and alignment | D13: 2-6 weeks | E13: Low to medium: enough data to prove the current condition | F13: The process owner, coached | G13: Open →
B14: 8D | C14: Customer complaint, safety event or regulatory issue requiring containment | D14: 24 h containment, 30-60 days to close | E14: Medium: containment evidence and root cause proof | F14: Quality lead with the process owner | G14: Open →
B15: Just Do It | C15: Cause and solution are both obvious, cost is low and risk is low | D15: Same day to two weeks | E15: Minimal: confirm the before and after | F15: Supervisor or operator | G15: Open →
B18: FIVE-QUESTION SCREENING
B20: YELLOW = overwrite with your data | C20: GREEN = calculated automatically
B22: No. | C22: Screening question | F22: Answer
B23: 1 | C23: Is a customer complaint, safety event or regulatory issue driving this? | F23: No
B24: 2 | C24: Is the root cause already known and agreed with evidence? | F24: No
B25: 3 | C25: Is the solution obvious, cheap (no capital) and low risk? | F25: No
B26: 4 | C26: Would answering this require statistical analysis of collected data? | F26: Yes
B27: 5 | C27: Could a cross-functional team finish the work in one focused week? | F27: No
B29: RECOMMENDED ROUTE | C29: =IF(F23="Yes","8D - contain within 24 hours, then close formally (H-15)",IF(F25="Yes","JUST DO IT - implement, verify the before and after, move on (L-23)",IF(AND(F24="Yes",F27="Yes"),"KAIZEN EVENT - one focused week with the team (L-21)",IF(AND(F24="Yes",F27="No"),"A3 - structured single-page project (H-14)",IF(F26="Yes","FULL DMAIC - the cause needs data and statistics (N-03)","A3 - start here and escalate to DMAIC only if the cause resists"))))) -> FULL DMAIC - the cause needs data and statistics (N-03)
B31: WHY THIS MATTERS
B33: • DMAIC earns its cost when the cause is genuinely unknown and the answer lives in data. That is the only condition under which four months of Measure and Analyze is cheaper than guessing.
B34: • If the cause is known and the fix is known, the value is in execution speed, not in analysis. Run a Kaizen event or simply do it, and spend the saved months on the next problem.
B35: • A customer or safety event overrides everything: contain first, analyse second. 8D exists because the customer needs protection before you need certainty.
B36: • The commonest failure is the reverse one: launching a Just Do It on a problem whose cause was never verified, then repeating the same fix three times in a year. If the fix has already failed once, escalate to a route with a validated root cause.

Sheet E-01 Data Types
A1: Made by Jose Zapatero, jmazsantos@gmail.com
B2: E-01 — Data Types and Measurement Scales | K2: MEASURE
B3: ← Back to Index | D3: Phase: MEASURE | Data required: Any variable list | Min. sample: n/a | Complexity: 1/5 | Typical output: Data classification and permitted statistics
B5: BLOCK 1 — QUICK CARD
B6: What question does this answer? | C6: What kind of data am I holding, and which statistics am I allowed to use on it?
B7: When you would reach for it | C7: Before any chart, test or capability study. It is the first decision of every project.
B8: What it gives you | C8: A classification and the list of tools that classification permits.
B10: BLOCK 2 — CONCEPT
B11: Every statistical method carries a hidden entry requirement: the measurement scale of your data.
B12: There are four scales. Nominal data only labels (machine 1, machine 2) - the numbers carry no order.
B13: Ordinal data has order but no fixed distance (taste panel 1 to 5; the gap 1-2 is not the gap 4-5).
B14: Interval data has fixed distances but an arbitrary zero (degrees Celsius: 40 C is not twice 20 C).
B15: Ratio data has fixed distances and a true zero (fill volume, torque, PU, dissolved oxygen).
B16: In practice the working split is simpler: attribute (nominal, ordinal) versus continuous (interval, ratio).
B17: Continuous data carries far more information per observation, which is why a capability study on 30 fill volumes tells you more than a p chart built from 30,000 pass/fail decisions.
B20: BLOCK 3 — WHEN TO USE / WHEN NOT TO USE / ASSUMPTIONS
B21: WHEN TO USE IT | E21: WHEN NOT TO USE IT
B22: ✓ At the start of every project, on every metric in the data collection plan. | E22: ✗ It is not a test - it produces no p-value.
B23: ✓ Whenever someone proposes averaging a score that is really a rank. | E23: ✗ It does not tell you whether the data is accurate, only what kind it is.
B24: ✓ When choosing between a variables chart and an attribute chart. | E24: ✗ Do not use it to justify converting continuous data into pass/fail: that destroys information.
B25: ✓ When deciding how much data you will need to collect.
B27: Assumption | C27: How to check it | D27: What to do if it fails | E27: Go to
B28: The measurement genuinely has the scale you claim | C28: Ask whether the zero is real and whether the gaps are equal | D28: Downgrade to the safer scale; treating ordinal as continuous inflates significance | E28: E-06 Operational Definitions and Data Collection Plan
B29: The variable is recorded at the resolution the scale implies | C29: Check the number of distinct values in the data | D29: If fewer than ten distinct values, treat as discrete regardless of the instrument | E29: E-59 Gage R&R: ANOVA and Range Methods
B30: Categories are mutually exclusive and exhaustive | C30: Check that no unit can be counted in two categories | D30: Redefine the categories in the operational definition | E30: E-06 Operational Definitions and Data Collection Plan
B32: BLOCK 4 — FORMULA AND DERIVATION
B33: No formula. The rule is a permission table.
B34: Nominal -> mode, counts, proportions. Mean is meaningless.
B35: Ordinal -> median, mode, percentiles. Mean is questionable.
B36: Interval -> mean, median, mode, standard deviation. Ratios are meaningless.
B37: Ratio -> everything, including coefficient of variation and geometric mean.
B38: Information content per observation, from lowest to highest:
B39: binary < nominal < ordinal < count < continuous
B41: BLOCK 5 — EXCEL IMPLEMENTATION
B42: Function used | C42: Syntax | D42: What the arguments mean
B43: INDEX | C43: INDEX(array, row_number) | D43: Returns the item in position row_number of the permission table
B44: MATCH | C44: MATCH(lookup_value, lookup_array, 0) | D44: Finds the row of the selected scale; 0 forces an exact match
B45: OR | C45: OR(test1, test2) | D45: TRUE if either test is TRUE - used to group the two attribute scales
B46: COUNTA | C46: COUNTA(range) | D46: Counts non-empty cells when auditing the plan
B47: Legacy function names are used throughout (STDEV, TDIST, NORMSDIST). They are accepted by every Excel version and by LibreOffice, and they avoid the unresolved-function name-resolution errors produced by the newer dotted names on some engines.
...

Sheet E-02 Population vs Sample
A1: Made by Jose Zapatero, jmazsantos@gmail.com
B2: E-02 — Population, Sample and Sampling Error | K2: MEASURE
B3: ← Back to Index | D3: Phase: MEASURE | Data required: Sample values | Min. sample: 5 | Complexity: 1/5 | Typical output: Sampling error estimate
B5: BLOCK 1 — QUICK CARD
B6: What question does this answer? | C6: How far can my sample be from the truth simply because it is a sample?
B7: When you would reach for it | C7: Whenever someone reacts to a difference between a sample average and a target.
B8: What it gives you | C8: The expected size of pure sampling noise, so you can tell it from a real shift.
B10: BLOCK 2 — CONCEPT
B11: You never measure the population. You measure a handful of bottles and hope they represent the shift.
B12: Two different samples from the same stable process will give two different averages. That difference is sampling error, and it is not a mistake: it is an unavoidable consequence of sampling.
B14: The size of that error is predictable. It shrinks with the square root of the sample size, which is why going from 4 to 16 bottles halves it, but going from 16 to 32 improves it by only 29 per cent.
B16: The practical consequence is blunt: if the observed gap between your sample mean and the target is smaller than the expected sampling error, you have no evidence of anything and adjusting the machine will make the process worse, not better. This is over-adjustment, and it is the commonest error on any line.
B20: BLOCK 3 — WHEN TO USE / WHEN NOT TO USE / ASSUMPTIONS
B21: WHEN TO USE IT | E21: WHEN NOT TO USE IT
B22: ✓ Before reacting to a single sample average that looks off target. | E22: ✗ Not a substitute for a hypothesis test when you need a formal p-value: use E-23.
B23: ✓ When explaining to a supervisor why two shifts 'always' differ slightly. | E23: ✗ Not valid if the sample was not taken at random from the population of interest.
B24: ✓ When sizing a sample so that the noise is smaller than the effect you care about. | E24: ✗ Does not detect bias: a badly calibrated gauge is wrong on every sample equally.
B26: Assumption | C26: How to check it | D26: What to do if it fails | E26: Go to
B27: The sample is representative of the population you want to describe | C27: Ask how the units were selected; convenience samples are not random | D27: Redesign the sampling plan before trusting any number | E27: E-05 Sampling Strategies and Rational Subgrouping
B28: Observations are independent | C28: Check that consecutive bottles are not from the same mould cavity | D28: Use rational subgrouping so that within-subgroup variation is short-term only | E28: E-05 Sampling Strategies and Rational Subgrouping
B29: The population standard deviation is stable | C29: Plot the data over time on a control chart | D29: If sigma is drifting, no single estimate of sampling error applies | E29: E-49 Individuals and Moving Range Chart
B31: BLOCK 4 — FORMULA AND DERIVATION
B32: Standard error of the mean (population sigma known):
B33: SE = sigma / SQRT(n)
B34: Estimated standard error (sigma unknown, estimated by s):
B35: SE = s / SQRT(n)
B36: Expected maximum sampling error at 95% confidence:
B37: E(max) = 1.96 * SE
B38: Observed sampling error expressed in standard error units:
B39: Z = (xbar - mu) / SE
B40: where mu = population mean (or the target), xbar = sample mean, n = sample size.
B42: BLOCK 5 — EXCEL IMPLEMENTATION
B43: Function used | C43: Syntax | D43: What the arguments mean
B44: AVERAGE | C44: AVERAGE(range) | D44: Sample mean of the measurements
B45: STDEV | C45: STDEV(range) | D45: Sample standard deviation, denominator n-1
B46: COUNT | C46: COUNT(range) | D46: Number of numeric observations
B47: SQRT | C47: SQRT(number) | D47: Square root, used in sigma divided by root n
B48: NORMSINV | C48: NORMSINV(probability) | D48: Standard normal quantile; NORMSINV(0.975) returns 1.96
B49: ABS | C49: ABS(number) | D49: Absolute value, so the comparison ignores the direction of the error
B50: Legacy function names are used throughout (STDEV, TDIST, NORMSDIST). They are accepted by every Excel version and by LibreOffice, and they avoid the unresolved-function name-resolution errors produced by the newer dotted names on some engines.
...

Sheet E-03 Descriptive Stats
A1: Made by Jose Zapatero, jmazsantos@gmail.com
B2: E-03 — Descriptive Statistics: Centre and Spread | K2: MEASURE
B3: ← Back to Index | D3: Phase: MEASURE | Data required: Continuous measurements | Min. sample: 10 | Complexity: 1/5 | Typical output: Mean, median, StDev, range, quartiles, histogram
B5: BLOCK 1 — QUICK CARD
B6: What question does this answer? | C6: Where is my process centred, how wide is it, and what shape is it?
B7: When you would reach for it | C7: The first numerical step of every Measure phase, before any chart or test.
B8: What it gives you | C8: Mean, median, standard deviation, range, quartiles, CV and a histogram.
B10: BLOCK 2 — CONCEPT
B11: Three questions describe any batch of measurements: where is it, how spread out is it, and what shape is it.
B12: Centre is usually the mean, but the median is the honest answer when the data is skewed or contains outliers:
B13: one bottle recorded at 540 ml because of a valve fault moves the mean and leaves the median untouched.
B14: Spread matters more than centre in packaging. A filler that is off target can be adjusted in a minute;
B15: a filler that is too variable is a project. Cp and Cpk on E-57 separate exactly these two problems.
B16: The coefficient of variation expresses spread as a percentage of the mean, which makes it the only fair way to compare the variability of a 500 ml SKU with that of a 1,500 ml SKU.
B18: Always plot the data before quoting a statistic. Two data sets with identical means and standard deviations can look completely different, and only the histogram will tell you.
B21: BLOCK 3 — WHEN TO USE / WHEN NOT TO USE / ASSUMPTIONS
B22: WHEN TO USE IT | E22: WHEN NOT TO USE IT
B23: ✓ Establishing the baseline of any project metric. | E23: ✗ Not a stability assessment: a stable and an unstable process can share the same mean and StDev.
B24: ✓ Before a capability study, to confirm the data is sensible. | E24: ✗ Do not quote Cp or Cpk from these numbers until the process is shown stable on E-49 or E-50.
B25: ✓ When comparing the spread of two SKUs of different nominal size (use the CV). | E25: ✗ Not meaningful on ordinal data: use the median and percentiles only.
B26: ✓ Whenever an outlier is suspected: compare mean against median.
B28: Assumption | C28: How to check it | D28: What to do if it fails | E28: Go to
B29: The data comes from one process, not several mixed together | C29: Look for two peaks in the histogram, and stratify by shift and cavity | D29: Split the data and describe each stream separately | E29: H-09 Stratification
B30: The measurement system is adequate | C30: Run a Gage R&R before trusting any spread statistic | D30: Fix the gauge first; the observed StDev includes the gauge StDev | E30: E-59 Gage R&R: ANOVA and Range Methods
B31: No outliers from a different cause | C31: Compare mean with median, and inspect the extreme values | D31: Investigate the cause before deleting anything, and never delete silently | E31: E-47 Common Cause vs Special Cause Variation
B33: BLOCK 4 — FORMULA AND DERIVATION
B34: Centre
B35: mean xbar = SUM(xi) / n
B36: median = middle value once sorted (average of the two middle values if n is even)
B37: Spread
B38: variance s^2 = SUM((xi - xbar)^2) / (n - 1)
B39: std dev s = SQRT(s^2)
B40: range R = max - min
B41: IQR = Q3 - Q1
B42: CV = s / xbar, expressed as a percentage
B43: Why n - 1 and not n:
B44: the deviations are taken from the sample mean rather than the unknown population mean, which uses up one degree of freedom. Dividing by n would under-estimate sigma.
B47: BLOCK 5 — EXCEL IMPLEMENTATION
B48: Function used | C48: Syntax | D48: What the arguments mean
B49: AVERAGE / MEDIAN / MODE | C49: AVERAGE(range) | D49: Three measures of centre
...

Sheet E-04 Skewness Kurtosis
A1: Made by Jose Zapatero, jmazsantos@gmail.com
B2: E-04 — Distribution Shape: Skewness and Kurtosis | K2: MEASURE
B3: ← Back to Index | D3: Phase: MEASURE | Data required: Continuous measurements | Min. sample: 25 | Complexity: 2/5 | Typical output: Skewness and kurtosis with interpretation
B5: BLOCK 1 — QUICK CARD
B6: What question does this answer? | C6: Is my distribution symmetric, and how heavy are its tails?
B7: When you would reach for it | C7: Before choosing between normal-theory capability and a non-normal method.
B8: What it gives you | C8: Skewness and kurtosis with their standard errors and a verdict on symmetry.
B10: BLOCK 2 — CONCEPT
B11: Skewness measures asymmetry. Zero means symmetric; positive means a long right tail; negative a long left tail.
B12: Filling processes are often slightly right skewed because a valve can stick open and overfill, but rarely under-fills by the same amount: the physical mechanisms are not symmetric.
B14: Kurtosis measures tail weight relative to a normal distribution. Excel reports excess kurtosis, so a normal distribution returns zero. Positive values mean heavier tails and more extreme values than normal theory expects.
B16: Neither statistic is a test on its own. Each is compared with its own standard error, which depends heavily on n: with 30 observations the standard error of skewness is about 0.43, so a skewness of 0.4 means nothing.
B18: This is why judging normality from skewness alone with a small sample is unreliable; use E-32 for a formal test.
B20: BLOCK 3 — WHEN TO USE / WHEN NOT TO USE / ASSUMPTIONS
B21: WHEN TO USE IT | E21: WHEN NOT TO USE IT
B22: ✓ Before a capability study, to anticipate whether normal theory will hold. | E22: ✗ Not a formal normality test: use E-32 for that.
B23: ✓ When a histogram looks lopsided and you need a number to support the impression. | E23: ✗ Unreliable below about 25 observations: the standard errors are enormous.
B24: ✓ When heavy tails are suspected because occasional extreme values appear. | E24: ✗ Do not use on data that mixes two streams; stratify first on H-09.
B26: Assumption | C26: How to check it | D26: What to do if it fails | E26: Go to
B27: Sample size is adequate | C27: n of at least 25, preferably 50 or more | D27: Collect more data before drawing conclusions about shape | E27: E-20 Sample Size Determination
B28: Data comes from a single process stream | C28: Stratify by shift, cavity and SKU and compare | D28: Split the data; a mixture can look skewed when both streams are symmetric | E28: H-09 Stratification
B29: Extreme values are genuine process output | C29: Trace each extreme value back to its production record | D29: Investigate the special cause rather than reporting the shape statistic | E29: E-47 Common Cause vs Special Cause Variation
B31: BLOCK 4 — FORMULA AND DERIVATION
B32: Skewness (Fisher-Pearson, the form Excel uses):
B33: g1 = n / ((n-1)(n-2)) * SUM( ((xi - xbar) / s)^3 )
B34: Excess kurtosis:
B35: g2 = n(n+1) / ((n-1)(n-2)(n-3)) * SUM( ((xi - xbar)/s)^4 ) - 3(n-1)^2 / ((n-2)(n-3))
B36: Standard errors:
B37: SE(skew) = SQRT( 6n(n-1) / ((n-2)(n+1)(n+3)) )
B38: SE(kurt) = 2 * SE(skew) * SQRT( (n^2 - 1) / ((n-3)(n+5)) )
B39: Test statistic for each:
B40: Z = statistic / its standard error. |Z| > 2 is evidence of departure from normality.
B42: BLOCK 5 — EXCEL IMPLEMENTATION
B43: Function used | C43: Syntax | D43: What the arguments mean
B44: SKEW | C44: SKEW(range) | D44: Fisher-Pearson sample skewness; requires at least three values
B45: KURT | C45: KURT(range) | D45: Excess kurtosis; returns 0 for a normal distribution, not 3
B46: COUNT | C46: COUNT(range) | D46: n, which drives both standard errors
B47: SQRT | C47: SQRT(number) | D47: Used in both standard error expressions
B48: ABS | C48: ABS(number) | D48: Compares the magnitude of Z against 2 regardless of sign
B49: Legacy function names are used throughout (STDEV, TDIST, NORMSDIST). They are accepted by every Excel version and by LibreOffice, and they avoid the unresolved-function name-resolution errors produced by the newer dotted names on some engines.
...

Sheet E-05 Sampling Subgroups
A1: Made by Jose Zapatero, jmazsantos@gmail.com
B2: E-05 — Sampling Strategies and Rational Subgrouping | K2: MEASURE
B3: ← Back to Index | D3: Phase: MEASURE | Data required: Process timeline and sources | Min. sample: n/a | Complexity: 3/5 | Typical output: Sampling plan and subgroup definition
B5: BLOCK 1 — QUICK CARD
B6: What question does this answer? | C6: How and when should I take my samples so that the chart can actually detect a problem?
B7: When you would reach for it | C7: When designing a control plan, an SPC scheme or the baseline data collection.
B8: What it gives you | C8: Subgroup size, sampling interval, and how long a shift would run before a shift is detected.
B10: BLOCK 2 — CONCEPT
B11: Rational subgrouping is the single most misunderstood idea in SPC, and it decides whether your chart works.
B12: The rule is simple to state: take the units inside a subgroup so close together that only common cause variation can act between them. Five consecutive bottles from the same filler over ten seconds is a rational subgroup. Five bottles taken one per hour across a shift is not: shift change, temperature drift and cavity differences all act inside that group.
B16: Why it matters: the within-subgroup spread sets the control limits. If you let long-term variation leak inside the subgroup, the limits become wide, the chart flags nothing, and everybody concludes SPC does not work.
B18: The opposite error is equally common. Taking all five bottles from valve 3 makes the subgroup so homogeneous that limits become absurdly tight and the chart flags constantly. Sample across all valves in rotation instead.
B20: The interval between subgroups is a separate decision, driven by how quickly you need to detect a shift and by how much product would be at risk in the meantime.
B23: BLOCK 3 — WHEN TO USE / WHEN NOT TO USE / ASSUMPTIONS
B24: WHEN TO USE IT | E24: WHEN NOT TO USE IT
B25: ✓ Designing any control chart scheme for the PET or keg line. | E25: ✗ Not applicable to one-off studies where all data is already collected.
B26: ✓ When an existing chart never signals, or signals constantly. | E26: ✗ Does not replace a measurement system analysis: sampling well from a bad gauge still fails.
B27: ✓ Setting the sampling frequency in the control plan on H-16. | E27: ✗ The detection calculation assumes the shift is sustained, not a single spike.
B28: ✓ Deciding how much product is at risk between two samples.
B30: Assumption | C30: How to check it | D30: What to do if it fails | E30: Go to
B31: Only common cause acts within a subgroup | C31: Ask what could change between the first and last unit of the subgroup | D31: Shorten the collection window or restructure the subgroup | E31: E-47 Common Cause vs Special Cause Variation
B32: Subgroups are representative of all streams | C32: Check that all valves, cavities or heads are sampled in rotation | D32: Rotate the sampling point, or chart each stream separately | E32: E-40 Multi-Vari Analysis
B33: The process is not being adjusted between samples | C33: Ask operators whether they tweak settings after each reading | D33: Stop the over-adjustment first; otherwise the chart measures the operator | E33: E-02 Population, Sample and Sampling Error
B35: BLOCK 4 — FORMULA AND DERIVATION
B36: Subgroups per shift:
B37: k = shift length in minutes / sampling interval in minutes
B38: Fraction of production actually measured:
B39: f = (k * n) / (line speed per hour * shift length in hours)
B40: Probability that one subgroup detects a sustained shift of delta sigma, with limits at +/- L sigma:
B41: p = 1 - NORMSDIST(L - delta*SQRT(n)) + NORMSDIST(-L - delta*SQRT(n))
B42: Average run length to signal, and the exposure it implies:
B43: ARL = 1 / p
B44: time to detect = ARL * sampling interval
B45: units at risk = time to detect / 60 * line speed per hour
B47: BLOCK 5 — EXCEL IMPLEMENTATION
B48: Function used | C48: Syntax | D48: What the arguments mean
B49: NORMSDIST | C49: NORMSDIST(z) | D49: Standard normal cumulative probability, used for both tails
B50: SQRT | C50: SQRT(n) | D50: Subgroup size enters the detection power through its square root
B51: IFERROR | C51: IFERROR(value, fallback) | D51: Guards the division when the detection probability is zero
B52: ROUND | C52: ROUND(number, digits) | D52: Presents subgroup counts as whole numbers
...

Sheet E-06 Data Collection Plan
A1: Made by Jose Zapatero, jmazsantos@gmail.com
B2: E-06 — Operational Definitions and Data Collection Plan | K2: MEASURE
B3: ← Back to Index | D3: Phase: MEASURE | Data required: Process and metric list | Min. sample: n/a | Complexity: 2/5 | Typical output: Operational definitions and collection plan
B5: BLOCK 1 — QUICK CARD
B6: What question does this answer? | C6: Will two different people, on two different shifts, record the same thing in the same way?
B7: When you would reach for it | C7: Before a single number is collected, in every project without exception.
B8: What it gives you | C8: An operational definition per metric and a completeness score for the plan.
B10: BLOCK 2 — CONCEPT
B11: An operational definition converts a word into a procedure. 'Label defect' is a word. 'A label whose leading edge deviates more than 2 mm from the reference mark, measured with the gauge at station 4, on a bottle taken from the discharge conveyor' is an operational definition.
B14: The test is simple and unforgiving: could two people, working independently on different shifts, follow the written text and reach the same number? If not, every statistic built on that data is decoration.
B16: Most measurement system failures on a packaging line are not instrument failures. They are definition failures:
